<?xml version="1.0" ?>
<robot xmlns:xacro="http://ros.org/wiki/xacro">
	<xacro:include filename="$(find reis_assets)/urdf/common_materials.xacro"/>

	<xacro:macro name="reis_rv240_180" params="prefix">
		<link name="${prefix}base_link">
			<visual>
				<origin xyz="0 0 0" rpy="0 0 0"/>
				<geometry>
					<mesh filename="package://reis_rv240_support/meshes/rv240_180/visual/base_link.stl"/>
				</geometry>
				<xacro:material_reis_black />
			</visual>
			<collision>
				<origin xyz="0 0 0" rpy="0 0 0"/>
				<geometry>
					<mesh filename="package://reis_rv240_support/meshes/rv240_180/collision/base_link.stl"/>
				</geometry>
			</collision>
		</link>
		<link name="${prefix}link_1">
			<visual>
				<origin xyz="0 0 0" rpy="0 0 0"/>
				<geometry>
					<mesh filename="package://reis_rv240_support/meshes/rv240_180/visual/link_1.stl"/>
				</geometry>
				<xacro:material_reis_red />
			</visual>
			<collision>
				<origin xyz="0 0 0" rpy="0 0 0"/>
				<geometry>
					<mesh filename="package://reis_rv240_support/meshes/rv240_180/collision/link_1.stl"/>
				</geometry>
			</collision>
		</link>
		<link name="${prefix}link_2">
			<visual>
				<origin xyz="0 0 0" rpy="0 0 0"/>
				<geometry>
					<mesh filename="package://reis_rv240_support/meshes/rv240_180/visual/link_2.stl"/>
				</geometry>
				<xacro:material_reis_red />
			</visual>
			<collision>
				<origin xyz="0 0 0" rpy="0 0 0"/>
				<geometry>
					<mesh filename="package://reis_rv240_support/meshes/rv240_180/collision/link_2.stl"/>
				</geometry>
			</collision>
		</link>
		<link name="${prefix}link_3">
			<visual>
				<origin xyz="0 0 0" rpy="0 0 0"/>
				<geometry>
					<mesh filename="package://reis_rv240_support/meshes/rv240_180/visual/link_3.stl"/>
				</geometry>
				<xacro:material_reis_red />
			</visual>
			<collision>
				<origin xyz="0 0 0" rpy="0 0 0"/>
				<geometry>
					<mesh filename="package://reis_rv240_support/meshes/rv240_180/collision/link_3.stl"/>
				</geometry>
			</collision>
		</link>
		<link name="${prefix}link_4">
			<visual>
				<origin xyz="0 0 0" rpy="0 0 0"/>
				<geometry>
					<mesh filename="package://reis_rv240_support/meshes/rv240_180/visual/link_4.stl"/>
				</geometry>
				<xacro:material_reis_red />
			</visual>
			<collision>
				<origin xyz="0 0 0" rpy="0 0 0"/>
				<geometry>
					<mesh filename="package://reis_rv240_support/meshes/rv240_180/collision/link_4.stl"/>
				</geometry>
			</collision>
		</link>
		<link name="${prefix}link_5">
			<visual>
				<origin xyz="0 0 0" rpy="0 0 0"/>
				<geometry>
					<mesh filename="package://reis_rv240_support/meshes/rv240_180/visual/link_5.stl"/>
				</geometry>
				<xacro:material_reis_red />
			</visual>
			<collision>
				<origin xyz="0 0 0" rpy="0 0 0"/>
				<geometry>
					<mesh filename="package://reis_rv240_support/meshes/rv240_180/collision/link_5.stl"/>
				</geometry>
			</collision>
		</link>
		<link name="${prefix}link_6">
			<visual>
				<origin xyz="0 0 0" rpy="0 0 0"/>
				<geometry>
					<mesh filename="package://reis_rv240_support/meshes/rv240_180/visual/link_6.stl"/>
				</geometry>
				<xacro:material_reis_black />
			</visual>
			<collision>
				<origin xyz="0 0 0" rpy="0 0 0"/>
				<geometry>
					<mesh filename="package://reis_rv240_support/meshes/rv240_180/collision/link_6.stl"/>
				</geometry>
			</collision>
		</link>
		<link name="${prefix}tool0" />


		<!-- extra links: balancer and rod -->
		<link name="${prefix}kolben">
			<visual>
				<origin xyz="0 0 0" rpy="0 0 0"/>
				<geometry>
					<mesh filename="package://reis_rv240_support/meshes/rv240_180/visual/kolben.stl"/>
				</geometry>
				<xacro:material_reis_black />
			</visual>
			<collision>
				<origin xyz="0 0 0" rpy="0 0 0"/>
				<geometry>
					<mesh filename="package://reis_rv240_support/meshes/rv240_180/collision/kolben.stl"/>
				</geometry>
			</collision>
		</link>
		<link name="${prefix}zylinder">
			<visual>
				<origin xyz="0 0 0" rpy="0 0 0"/>
				<geometry>
					<mesh filename="package://reis_rv240_support/meshes/rv240_180/visual/zylinder.stl"/>
				</geometry>
				<xacro:material_reis_black />
			</visual>
			<collision>
				<origin xyz="0 0 0" rpy="0 0 0"/>
				<geometry>
					<mesh filename="package://reis_rv240_support/meshes/rv240_180/collision/zylinder.stl"/>
				</geometry>
			</collision>
		</link>


		<joint name="${prefix}joint_1" type="revolute">
			<origin xyz="0 0 0.30065" rpy="0 0 0"/>
			<parent link="${prefix}base_link"/>
			<child link="${prefix}link_1"/>
			<axis xyz="0 0 -1"/>
			<limit lower="-3.14" upper="3.14" effort="0" velocity="1.43"/>
		</joint>
		<joint name="${prefix}joint_2" type="revolute">
			<origin xyz="0.35 0 0.44935" rpy="0 0 0"/>
			<parent link="${prefix}link_1"/>
			<child link="${prefix}link_2"/>
			<axis xyz="0 1 0"/>
			<limit lower="-2.55" upper="1" effort="0" velocity="1.36"/>
		</joint>
		<joint name="${prefix}joint_3" type="revolute">
			<origin xyz="0 0 1.25" rpy="0 0 0"/>
			<parent link="${prefix}link_2"/>
			<child link="${prefix}link_3"/>
			<axis xyz="0 1 0"/>
			<limit lower="-2.08" upper="2.71" effort="0" velocity="1.33"/>
		</joint>
		<joint name="${prefix}joint_4" type="revolute">
			<origin xyz="0 0 -0.055" rpy="0 0 0"/>
			<parent link="${prefix}link_3"/>
			<child link="${prefix}link_4"/>
			<axis xyz="1 0 0"/>
			<limit lower="-6.11" upper="6.11" effort="0" velocity="1.75"/>
		</joint>
		<joint name="${prefix}joint_5" type="revolute">
			<origin xyz="1.5 0 0" rpy="0 0 0"/>
			<parent link="${prefix}link_4"/>
			<child link="${prefix}link_5"/>
			<axis xyz="0 1 0"/>
			<limit lower="-2.18" upper="2.18" effort="0" velocity="1.92"/>
		</joint>
		<joint name="${prefix}joint_6" type="revolute">
			<origin xyz="0 0 0" rpy="0 0 0"/>
			<parent link="${prefix}link_5"/>
			<child link="${prefix}link_6"/>
			<axis xyz="1 0 0"/>
			<limit lower="-6.11" upper="6.11" effort="0" velocity="3.21"/>
		</joint>
		<joint name="${prefix}joint_6-tool0" type="fixed">
			<parent link="${prefix}link_6"/>
			<child link="${prefix}tool0"/>
			<origin xyz="0 0 0" rpy="0 0 0"/>
		</joint>


		<!-- extra joints: balancer and rod -->
		<joint name="${prefix}link2_kolb_joint" type="revolute">
			<origin xyz="-0.54782 -0.23325 -0.10066" rpy="0 -0.18528 1.4987E-15"/>
			<parent link="${prefix}link_2"/>
			<child link="${prefix}kolben"/>
			<axis xyz="0 1 0"/>
			<limit lower="-6.28" upper="6.28" effort="0" velocity="3.14"/>
		</joint>
		<joint name="${prefix}link1_zyl_joint" type="revolute">
			<origin xyz="-0.3357 -0.01455 0.32285" rpy="-2.7159E-16 -0.18528 1.4742E-15"/>
			<parent link="${prefix}link_1"/>
			<child link="${prefix}zylinder"/>
			<axis xyz="0 1 0"/>
			<limit lower="-6.28" upper="6.28" effort="0" velocity="3.14"/>
		</joint>
	</xacro:macro>
</robot>
