<?xml version="1.0" ?>
<!-- =================================================================================== -->
<!-- |    This document was autogenerated by xacro from rv240_180.xacro                | -->
<!-- |    EDITING THIS FILE BY HAND IS NOT RECOMMENDED                                 | -->
<!-- =================================================================================== -->
<robot name="reis_rv240_180" xmlns:xacro="http://ros.org/wiki/xacro">
  <link name="base_link">
    <visual>
      <origin rpy="0 0 0" xyz="0 0 0"/>
      <geometry>
        <mesh filename="package://reis_rv240_support/meshes/rv240_180/visual/base_link.stl"/>
      </geometry>
      <material name="">
        <color rgba="0.059 0.11  0.17  1.0"/>
      </material>
    </visual>
    <collision>
      <origin rpy="0 0 0" xyz="0 0 0"/>
      <geometry>
        <mesh filename="package://reis_rv240_support/meshes/rv240_180/collision/base_link.stl"/>
      </geometry>
    </collision>
  </link>
  <link name="link_1">
    <visual>
      <origin rpy="0 0 0" xyz="0 0 0"/>
      <geometry>
        <mesh filename="package://reis_rv240_support/meshes/rv240_180/visual/link_1.stl"/>
      </geometry>
      <material name="">
        <color rgba="0.74  0.016 0.016 1.0"/>
      </material>
    </visual>
    <collision>
      <origin rpy="0 0 0" xyz="0 0 0"/>
      <geometry>
        <mesh filename="package://reis_rv240_support/meshes/rv240_180/collision/link_1.stl"/>
      </geometry>
    </collision>
  </link>
  <link name="link_2">
    <visual>
      <origin rpy="0 0 0" xyz="0 0 0"/>
      <geometry>
        <mesh filename="package://reis_rv240_support/meshes/rv240_180/visual/link_2.stl"/>
      </geometry>
      <material name="">
        <color rgba="0.74  0.016 0.016 1.0"/>
      </material>
    </visual>
    <collision>
      <origin rpy="0 0 0" xyz="0 0 0"/>
      <geometry>
        <mesh filename="package://reis_rv240_support/meshes/rv240_180/collision/link_2.stl"/>
      </geometry>
    </collision>
  </link>
  <link name="link_3">
    <visual>
      <origin rpy="0 0 0" xyz="0 0 0"/>
      <geometry>
        <mesh filename="package://reis_rv240_support/meshes/rv240_180/visual/link_3.stl"/>
      </geometry>
      <material name="">
        <color rgba="0.74  0.016 0.016 1.0"/>
      </material>
    </visual>
    <collision>
      <origin rpy="0 0 0" xyz="0 0 0"/>
      <geometry>
        <mesh filename="package://reis_rv240_support/meshes/rv240_180/collision/link_3.stl"/>
      </geometry>
    </collision>
  </link>
  <link name="link_4">
    <visual>
      <origin rpy="0 0 0" xyz="0 0 0"/>
      <geometry>
        <mesh filename="package://reis_rv240_support/meshes/rv240_180/visual/link_4.stl"/>
      </geometry>
      <material name="">
        <color rgba="0.74  0.016 0.016 1.0"/>
      </material>
    </visual>
    <collision>
      <origin rpy="0 0 0" xyz="0 0 0"/>
      <geometry>
        <mesh filename="package://reis_rv240_support/meshes/rv240_180/collision/link_4.stl"/>
      </geometry>
    </collision>
  </link>
  <link name="link_5">
    <visual>
      <origin rpy="0 0 0" xyz="0 0 0"/>
      <geometry>
        <mesh filename="package://reis_rv240_support/meshes/rv240_180/visual/link_5.stl"/>
      </geometry>
      <material name="">
        <color rgba="0.74  0.016 0.016 1.0"/>
      </material>
    </visual>
    <collision>
      <origin rpy="0 0 0" xyz="0 0 0"/>
      <geometry>
        <mesh filename="package://reis_rv240_support/meshes/rv240_180/collision/link_5.stl"/>
      </geometry>
    </collision>
  </link>
  <link name="link_6">
    <visual>
      <origin rpy="0 0 0" xyz="0 0 0"/>
      <geometry>
        <mesh filename="package://reis_rv240_support/meshes/rv240_180/visual/link_6.stl"/>
      </geometry>
      <material name="">
        <color rgba="0.059 0.11  0.17  1.0"/>
      </material>
    </visual>
    <collision>
      <origin rpy="0 0 0" xyz="0 0 0"/>
      <geometry>
        <mesh filename="package://reis_rv240_support/meshes/rv240_180/collision/link_6.stl"/>
      </geometry>
    </collision>
  </link>
  <link name="tool0"/>
  <link name="kolben">
    <visual>
      <origin rpy="0 0 0" xyz="0 0 0"/>
      <geometry>
        <mesh filename="package://reis_rv240_support/meshes/rv240_180/visual/kolben.stl"/>
      </geometry>
      <material name="">
        <color rgba="0.059 0.11  0.17  1.0"/>
      </material>
    </visual>
    <collision>
      <origin rpy="0 0 0" xyz="0 0 0"/>
      <geometry>
        <mesh filename="package://reis_rv240_support/meshes/rv240_180/collision/kolben.stl"/>
      </geometry>
    </collision>
  </link>
  <link name="zylinder">
    <visual>
      <origin rpy="0 0 0" xyz="0 0 0"/>
      <geometry>
        <mesh filename="package://reis_rv240_support/meshes/rv240_180/visual/zylinder.stl"/>
      </geometry>
      <material name="">
        <color rgba="0.059 0.11  0.17  1.0"/>
      </material>
    </visual>
    <collision>
      <origin rpy="0 0 0" xyz="0 0 0"/>
      <geometry>
        <mesh filename="package://reis_rv240_support/meshes/rv240_180/collision/zylinder.stl"/>
      </geometry>
    </collision>
  </link>
  <joint name="joint_1" type="revolute">
    <origin rpy="0 0 0" xyz="0 0 0.30065"/>
    <parent link="base_link"/>
    <child link="link_1"/>
    <axis xyz="0 0 -1"/>
    <limit effort="0" lower="-3.14" upper="3.14" velocity="1.43"/>
  </joint>
  <joint name="joint_2" type="revolute">
    <origin rpy="0 0 0" xyz="0.35 0 0.44935"/>
    <parent link="link_1"/>
    <child link="link_2"/>
    <axis xyz="0 1 0"/>
    <limit effort="0" lower="-2.55" upper="1" velocity="1.36"/>
  </joint>
  <joint name="joint_3" type="revolute">
    <origin rpy="0 0 0" xyz="0 0 1.25"/>
    <parent link="link_2"/>
    <child link="link_3"/>
    <axis xyz="0 1 0"/>
    <limit effort="0" lower="-2.08" upper="2.71" velocity="1.33"/>
  </joint>
  <joint name="joint_4" type="revolute">
    <origin rpy="0 0 0" xyz="0 0 -0.055"/>
    <parent link="link_3"/>
    <child link="link_4"/>
    <axis xyz="1 0 0"/>
    <limit effort="0" lower="-6.11" upper="6.11" velocity="1.75"/>
  </joint>
  <joint name="joint_5" type="revolute">
    <origin rpy="0 0 0" xyz="1.5 0 0"/>
    <parent link="link_4"/>
    <child link="link_5"/>
    <axis xyz="0 1 0"/>
    <limit effort="0" lower="-2.18" upper="2.18" velocity="1.92"/>
  </joint>
  <joint name="joint_6" type="revolute">
    <origin rpy="0 0 0" xyz="0 0 0"/>
    <parent link="link_5"/>
    <child link="link_6"/>
    <axis xyz="1 0 0"/>
    <limit effort="0" lower="-6.11" upper="6.11" velocity="3.21"/>
  </joint>
  <joint name="joint_6-tool0" type="fixed">
    <parent link="link_6"/>
    <child link="tool0"/>
    <origin rpy="0 0 0" xyz="0 0 0"/>
  </joint>
  <joint name="link2_kolb_joint" type="revolute">
    <origin rpy="0 -0.18528 1.4987E-15" xyz="-0.54782 -0.23325 -0.10066"/>
    <parent link="link_2"/>
    <child link="kolben"/>
    <axis xyz="0 1 0"/>
    <limit effort="0" lower="-6.28" upper="6.28" velocity="3.14"/>
  </joint>
  <joint name="link1_zyl_joint" type="revolute">
    <origin rpy="-2.7159E-16 -0.18528 1.4742E-15" xyz="-0.3357 -0.01455 0.32285"/>
    <parent link="link_1"/>
    <child link="zylinder"/>
    <axis xyz="0 1 0"/>
    <limit effort="0" lower="-6.28" upper="6.28" velocity="3.14"/>
  </joint>
</robot>
